2024-06-29 03:10:40,692 INFO Watching for file changes with StatReloader
2024-06-29 03:15:22,435 INFO Watching for file changes with StatReloader
2024-06-29 03:18:01,824 INFO Watching for file changes with StatReloader
2024-06-29 03:23:16,753 INFO Watching for file changes with StatReloader
2024-06-29 03:26:19,331 ERROR Internal Server Error: /admin/
Traceback (most recent call last):
  File "C:\Users\katit\AppData\Local\Programs\Python\Python312\Lib\site-packages\django\contrib\sessions\backends\base.py", line 187, in _get_session
    return self._session_cache
           ^^^^^^^^^^^^^^^^^^^
AttributeError: 'SessionStore' object has no attribute '_session_cache'

During handling of the above exception, another exception occurred:

Traceback (most recent call last):
  File "C:\Users\katit\AppData\Local\Programs\Python\Python312\Lib\site-packages\django\db\backends\utils.py", line 105, in _execute
    return self.cursor.execute(sql, params)
           ^^^^^^^^^^^^^^^^^^^^^^^^^^^^^^^^
  File "C:\Users\katit\AppData\Local\Programs\Python\Python312\Lib\site-packages\django\db\backends\sqlite3\base.py", line 329, in execute
    return super().execute(query, params)
           ^^^^^^^^^^^^^^^^^^^^^^^^^^^^^^
sqlite3.OperationalError: no such table: django_session

The above exception was the direct cause of the following exception:

Traceback (most recent call last):
  File "C:\Users\katit\AppData\Local\Programs\Python\Python312\Lib\site-packages\django\core\handlers\exception.py", line 55, in inner
    response = get_response(request)
               ^^^^^^^^^^^^^^^^^^^^^
  File "C:\Users\katit\AppData\Local\Programs\Python\Python312\Lib\site-packages\django\core\handlers\base.py", line 197, in _get_response
    response = wrapped_callback(request, *callback_args, **callback_kwargs)
               ^^^^^^^^^^^^^^^^^^^^^^^^^^^^^^^^^^^^^^^^^^^^^^^^^^^^^^^^^^^^
  File "C:\Users\katit\AppData\Local\Programs\Python\Python312\Lib\site-packages\django\contrib\admin\sites.py", line 259, in wrapper
    return self.admin_view(view, cacheable)(*args, **kwargs)
           ^^^^^^^^^^^^^^^^^^^^^^^^^^^^^^^^^^^^^^^^^^^^^^^^^
  File "C:\Users\katit\AppData\Local\Programs\Python\Python312\Lib\site-packages\django\utils\decorators.py", line 188, in _view_wrapper
    result = _process_exception(request, e)
             ^^^^^^^^^^^^^^^^^^^^^^^^^^^^^^
  File "C:\Users\katit\AppData\Local\Programs\Python\Python312\Lib\site-packages\django\utils\decorators.py", line 186, in _view_wrapper
    response = view_func(request, *args, **kwargs)
               ^^^^^^^^^^^^^^^^^^^^^^^^^^^^^^^^^^^
  File "C:\Users\katit\AppData\Local\Programs\Python\Python312\Lib\site-packages\django\views\decorators\cache.py", line 80, in _view_wrapper
    response = view_func(request, *args, **kwargs)
               ^^^^^^^^^^^^^^^^^^^^^^^^^^^^^^^^^^^
  File "C:\Users\katit\AppData\Local\Programs\Python\Python312\Lib\site-packages\django\contrib\admin\sites.py", line 228, in inner
    if not self.has_permission(request):
           ^^^^^^^^^^^^^^^^^^^^^^^^^^^^
  File "C:\Users\katit\AppData\Local\Programs\Python\Python312\Lib\site-packages\django\contrib\admin\sites.py", line 201, in has_permission
    return request.user.is_active and request.user.is_staff
           ^^^^^^^^^^^^^^^^^^^^^^
  File "C:\Users\katit\AppData\Local\Programs\Python\Python312\Lib\site-packages\django\utils\functional.py", line 251, in inner
    self._setup()
  File "C:\Users\katit\AppData\Local\Programs\Python\Python312\Lib\site-packages\django\utils\functional.py", line 404, in _setup
    self._wrapped = self._setupfunc()
                    ^^^^^^^^^^^^^^^^^
  File "C:\Users\katit\AppData\Local\Programs\Python\Python312\Lib\site-packages\django\contrib\auth\middleware.py", line 33, in <lambda>
    request.user = SimpleLazyObject(lambda: get_user(request))
                                            ^^^^^^^^^^^^^^^^^
  File "C:\Users\katit\AppData\Local\Programs\Python\Python312\Lib\site-packages\django\contrib\auth\middleware.py", line 13, in get_user
    request._cached_user = auth.get_user(request)
                           ^^^^^^^^^^^^^^^^^^^^^^
  File "C:\Users\katit\AppData\Local\Programs\Python\Python312\Lib\site-packages\django\contrib\auth\__init__.py", line 209, in get_user
    user_id = _get_user_session_key(request)
              ^^^^^^^^^^^^^^^^^^^^^^^^^^^^^^
  File "C:\Users\katit\AppData\Local\Programs\Python\Python312\Lib\site-packages\django\contrib\auth\__init__.py", line 62, in _get_user_session_key
    return get_user_model()._meta.pk.to_python(request.session[SESSION_KEY])
                                               ~~~~~~~~~~~~~~~^^^^^^^^^^^^^
  File "C:\Users\katit\AppData\Local\Programs\Python\Python312\Lib\site-packages\django\contrib\sessions\backends\base.py", line 53, in __getitem__
    return self._session[key]
           ^^^^^^^^^^^^^
  File "C:\Users\katit\AppData\Local\Programs\Python\Python312\Lib\site-packages\django\contrib\sessions\backends\base.py", line 192, in _get_session
    self._session_cache = self.load()
                          ^^^^^^^^^^^
  File "C:\Users\katit\AppData\Local\Programs\Python\Python312\Lib\site-packages\django\contrib\sessions\backends\db.py", line 42, in load
    s = self._get_session_from_db()
        ^^^^^^^^^^^^^^^^^^^^^^^^^^^
  File "C:\Users\katit\AppData\Local\Programs\Python\Python312\Lib\site-packages\django\contrib\sessions\backends\db.py", line 32, in _get_session_from_db
    return self.model.objects.get(
           ^^^^^^^^^^^^^^^^^^^^^^^
  File "C:\Users\katit\AppData\Local\Programs\Python\Python312\Lib\site-packages\django\db\models\manager.py", line 87, in manager_method
    return getattr(self.get_queryset(), name)(*args, **kwargs)
           ^^^^^^^^^^^^^^^^^^^^^^^^^^^^^^^^^^^^^^^^^^^^^^^^^^^
  File "C:\Users\katit\AppData\Local\Programs\Python\Python312\Lib\site-packages\django\db\models\query.py", line 645, in get
    num = len(clone)
          ^^^^^^^^^^
  File "C:\Users\katit\AppData\Local\Programs\Python\Python312\Lib\site-packages\django\db\models\query.py", line 382, in __len__
    self._fetch_all()
  File "C:\Users\katit\AppData\Local\Programs\Python\Python312\Lib\site-packages\django\db\models\query.py", line 1928, in _fetch_all
    self._result_cache = list(self._iterable_class(self))
                         ^^^^^^^^^^^^^^^^^^^^^^^^^^^^^^^^
  File "C:\Users\katit\AppData\Local\Programs\Python\Python312\Lib\site-packages\django\db\models\query.py", line 91, in __iter__
    results = compiler.execute_sql(
              ^^^^^^^^^^^^^^^^^^^^^
  File "C:\Users\katit\AppData\Local\Programs\Python\Python312\Lib\site-packages\django\db\models\sql\compiler.py", line 1562, in execute_sql
    cursor.execute(sql, params)
  File "C:\Users\katit\AppData\Local\Programs\Python\Python312\Lib\site-packages\django\db\backends\utils.py", line 122, in execute
    return super().execute(sql, params)
           ^^^^^^^^^^^^^^^^^^^^^^^^^^^^
  File "C:\Users\katit\AppData\Local\Programs\Python\Python312\Lib\site-packages\django\db\backends\utils.py", line 79, in execute
    return self._execute_with_wrappers(
           ^^^^^^^^^^^^^^^^^^^^^^^^^^^^
  File "C:\Users\katit\AppData\Local\Programs\Python\Python312\Lib\site-packages\django\db\backends\utils.py", line 92, in _execute_with_wrappers
    return executor(sql, params, many, context)
           ^^^^^^^^^^^^^^^^^^^^^^^^^^^^^^^^^^^^
  File "C:\Users\katit\AppData\Local\Programs\Python\Python312\Lib\site-packages\django\db\backends\utils.py", line 100, in _execute
    with self.db.wrap_database_errors:
  File "C:\Users\katit\AppData\Local\Programs\Python\Python312\Lib\site-packages\django\db\utils.py", line 91, in __exit__
    raise dj_exc_value.with_traceback(traceback) from exc_value
  File "C:\Users\katit\AppData\Local\Programs\Python\Python312\Lib\site-packages\django\db\backends\utils.py", line 105, in _execute
    return self.cursor.execute(sql, params)
           ^^^^^^^^^^^^^^^^^^^^^^^^^^^^^^^^
  File "C:\Users\katit\AppData\Local\Programs\Python\Python312\Lib\site-packages\django\db\backends\sqlite3\base.py", line 329, in execute
    return super().execute(query, params)
           ^^^^^^^^^^^^^^^^^^^^^^^^^^^^^^
django.db.utils.OperationalError: no such table: django_session
2024-06-29 03:26:21,139 ERROR Internal Server Error: /admin/
Traceback (most recent call last):
  File "C:\Users\katit\AppData\Local\Programs\Python\Python312\Lib\site-packages\django\contrib\sessions\backends\base.py", line 187, in _get_session
    return self._session_cache
           ^^^^^^^^^^^^^^^^^^^
AttributeError: 'SessionStore' object has no attribute '_session_cache'

During handling of the above exception, another exception occurred:

Traceback (most recent call last):
  File "C:\Users\katit\AppData\Local\Programs\Python\Python312\Lib\site-packages\django\db\backends\utils.py", line 105, in _execute
    return self.cursor.execute(sql, params)
           ^^^^^^^^^^^^^^^^^^^^^^^^^^^^^^^^
  File "C:\Users\katit\AppData\Local\Programs\Python\Python312\Lib\site-packages\django\db\backends\sqlite3\base.py", line 329, in execute
    return super().execute(query, params)
           ^^^^^^^^^^^^^^^^^^^^^^^^^^^^^^
sqlite3.OperationalError: no such table: django_session

The above exception was the direct cause of the following exception:

Traceback (most recent call last):
  File "C:\Users\katit\AppData\Local\Programs\Python\Python312\Lib\site-packages\django\core\handlers\exception.py", line 55, in inner
    response = get_response(request)
               ^^^^^^^^^^^^^^^^^^^^^
  File "C:\Users\katit\AppData\Local\Programs\Python\Python312\Lib\site-packages\django\core\handlers\base.py", line 197, in _get_response
    response = wrapped_callback(request, *callback_args, **callback_kwargs)
               ^^^^^^^^^^^^^^^^^^^^^^^^^^^^^^^^^^^^^^^^^^^^^^^^^^^^^^^^^^^^
  File "C:\Users\katit\AppData\Local\Programs\Python\Python312\Lib\site-packages\django\contrib\admin\sites.py", line 259, in wrapper
    return self.admin_view(view, cacheable)(*args, **kwargs)
           ^^^^^^^^^^^^^^^^^^^^^^^^^^^^^^^^^^^^^^^^^^^^^^^^^
  File "C:\Users\katit\AppData\Local\Programs\Python\Python312\Lib\site-packages\django\utils\decorators.py", line 188, in _view_wrapper
    result = _process_exception(request, e)
             ^^^^^^^^^^^^^^^^^^^^^^^^^^^^^^
  File "C:\Users\katit\AppData\Local\Programs\Python\Python312\Lib\site-packages\django\utils\decorators.py", line 186, in _view_wrapper
    response = view_func(request, *args, **kwargs)
               ^^^^^^^^^^^^^^^^^^^^^^^^^^^^^^^^^^^
  File "C:\Users\katit\AppData\Local\Programs\Python\Python312\Lib\site-packages\django\views\decorators\cache.py", line 80, in _view_wrapper
    response = view_func(request, *args, **kwargs)
               ^^^^^^^^^^^^^^^^^^^^^^^^^^^^^^^^^^^
  File "C:\Users\katit\AppData\Local\Programs\Python\Python312\Lib\site-packages\django\contrib\admin\sites.py", line 228, in inner
    if not self.has_permission(request):
           ^^^^^^^^^^^^^^^^^^^^^^^^^^^^
  File "C:\Users\katit\AppData\Local\Programs\Python\Python312\Lib\site-packages\django\contrib\admin\sites.py", line 201, in has_permission
    return request.user.is_active and request.user.is_staff
           ^^^^^^^^^^^^^^^^^^^^^^
  File "C:\Users\katit\AppData\Local\Programs\Python\Python312\Lib\site-packages\django\utils\functional.py", line 251, in inner
    self._setup()
  File "C:\Users\katit\AppData\Local\Programs\Python\Python312\Lib\site-packages\django\utils\functional.py", line 404, in _setup
    self._wrapped = self._setupfunc()
                    ^^^^^^^^^^^^^^^^^
  File "C:\Users\katit\AppData\Local\Programs\Python\Python312\Lib\site-packages\django\contrib\auth\middleware.py", line 33, in <lambda>
    request.user = SimpleLazyObject(lambda: get_user(request))
                                            ^^^^^^^^^^^^^^^^^
  File "C:\Users\katit\AppData\Local\Programs\Python\Python312\Lib\site-packages\django\contrib\auth\middleware.py", line 13, in get_user
    request._cached_user = auth.get_user(request)
                           ^^^^^^^^^^^^^^^^^^^^^^
  File "C:\Users\katit\AppData\Local\Programs\Python\Python312\Lib\site-packages\django\contrib\auth\__init__.py", line 209, in get_user
    user_id = _get_user_session_key(request)
              ^^^^^^^^^^^^^^^^^^^^^^^^^^^^^^
  File "C:\Users\katit\AppData\Local\Programs\Python\Python312\Lib\site-packages\django\contrib\auth\__init__.py", line 62, in _get_user_session_key
    return get_user_model()._meta.pk.to_python(request.session[SESSION_KEY])
                                               ~~~~~~~~~~~~~~~^^^^^^^^^^^^^
  File "C:\Users\katit\AppData\Local\Programs\Python\Python312\Lib\site-packages\django\contrib\sessions\backends\base.py", line 53, in __getitem__
    return self._session[key]
           ^^^^^^^^^^^^^
  File "C:\Users\katit\AppData\Local\Programs\Python\Python312\Lib\site-packages\django\contrib\sessions\backends\base.py", line 192, in _get_session
    self._session_cache = self.load()
                          ^^^^^^^^^^^
  File "C:\Users\katit\AppData\Local\Programs\Python\Python312\Lib\site-packages\django\contrib\sessions\backends\db.py", line 42, in load
    s = self._get_session_from_db()
        ^^^^^^^^^^^^^^^^^^^^^^^^^^^
  File "C:\Users\katit\AppData\Local\Programs\Python\Python312\Lib\site-packages\django\contrib\sessions\backends\db.py", line 32, in _get_session_from_db
    return self.model.objects.get(
           ^^^^^^^^^^^^^^^^^^^^^^^
  File "C:\Users\katit\AppData\Local\Programs\Python\Python312\Lib\site-packages\django\db\models\manager.py", line 87, in manager_method
    return getattr(self.get_queryset(), name)(*args, **kwargs)
           ^^^^^^^^^^^^^^^^^^^^^^^^^^^^^^^^^^^^^^^^^^^^^^^^^^^
  File "C:\Users\katit\AppData\Local\Programs\Python\Python312\Lib\site-packages\django\db\models\query.py", line 645, in get
    num = len(clone)
          ^^^^^^^^^^
  File "C:\Users\katit\AppData\Local\Programs\Python\Python312\Lib\site-packages\django\db\models\query.py", line 382, in __len__
    self._fetch_all()
  File "C:\Users\katit\AppData\Local\Programs\Python\Python312\Lib\site-packages\django\db\models\query.py", line 1928, in _fetch_all
    self._result_cache = list(self._iterable_class(self))
                         ^^^^^^^^^^^^^^^^^^^^^^^^^^^^^^^^
  File "C:\Users\katit\AppData\Local\Programs\Python\Python312\Lib\site-packages\django\db\models\query.py", line 91, in __iter__
    results = compiler.execute_sql(
              ^^^^^^^^^^^^^^^^^^^^^
  File "C:\Users\katit\AppData\Local\Programs\Python\Python312\Lib\site-packages\django\db\models\sql\compiler.py", line 1562, in execute_sql
    cursor.execute(sql, params)
  File "C:\Users\katit\AppData\Local\Programs\Python\Python312\Lib\site-packages\django\db\backends\utils.py", line 122, in execute
    return super().execute(sql, params)
           ^^^^^^^^^^^^^^^^^^^^^^^^^^^^
  File "C:\Users\katit\AppData\Local\Programs\Python\Python312\Lib\site-packages\django\db\backends\utils.py", line 79, in execute
    return self._execute_with_wrappers(
           ^^^^^^^^^^^^^^^^^^^^^^^^^^^^
  File "C:\Users\katit\AppData\Local\Programs\Python\Python312\Lib\site-packages\django\db\backends\utils.py", line 92, in _execute_with_wrappers
    return executor(sql, params, many, context)
           ^^^^^^^^^^^^^^^^^^^^^^^^^^^^^^^^^^^^
  File "C:\Users\katit\AppData\Local\Programs\Python\Python312\Lib\site-packages\django\db\backends\utils.py", line 100, in _execute
    with self.db.wrap_database_errors:
  File "C:\Users\katit\AppData\Local\Programs\Python\Python312\Lib\site-packages\django\db\utils.py", line 91, in __exit__
    raise dj_exc_value.with_traceback(traceback) from exc_value
  File "C:\Users\katit\AppData\Local\Programs\Python\Python312\Lib\site-packages\django\db\backends\utils.py", line 105, in _execute
    return self.cursor.execute(sql, params)
           ^^^^^^^^^^^^^^^^^^^^^^^^^^^^^^^^
  File "C:\Users\katit\AppData\Local\Programs\Python\Python312\Lib\site-packages\django\db\backends\sqlite3\base.py", line 329, in execute
    return super().execute(query, params)
           ^^^^^^^^^^^^^^^^^^^^^^^^^^^^^^
django.db.utils.OperationalError: no such table: django_session
2024-06-29 03:26:26,849 ERROR Internal Server Error: /admin/
Traceback (most recent call last):
  File "C:\Users\katit\AppData\Local\Programs\Python\Python312\Lib\site-packages\django\contrib\sessions\backends\base.py", line 187, in _get_session
    return self._session_cache
           ^^^^^^^^^^^^^^^^^^^
AttributeError: 'SessionStore' object has no attribute '_session_cache'

During handling of the above exception, another exception occurred:

Traceback (most recent call last):
  File "C:\Users\katit\AppData\Local\Programs\Python\Python312\Lib\site-packages\django\db\backends\utils.py", line 105, in _execute
    return self.cursor.execute(sql, params)
           ^^^^^^^^^^^^^^^^^^^^^^^^^^^^^^^^
  File "C:\Users\katit\AppData\Local\Programs\Python\Python312\Lib\site-packages\django\db\backends\sqlite3\base.py", line 329, in execute
    return super().execute(query, params)
           ^^^^^^^^^^^^^^^^^^^^^^^^^^^^^^
sqlite3.OperationalError: no such table: django_session

The above exception was the direct cause of the following exception:

Traceback (most recent call last):
  File "C:\Users\katit\AppData\Local\Programs\Python\Python312\Lib\site-packages\django\core\handlers\exception.py", line 55, in inner
    response = get_response(request)
               ^^^^^^^^^^^^^^^^^^^^^
  File "C:\Users\katit\AppData\Local\Programs\Python\Python312\Lib\site-packages\django\core\handlers\base.py", line 197, in _get_response
    response = wrapped_callback(request, *callback_args, **callback_kwargs)
               ^^^^^^^^^^^^^^^^^^^^^^^^^^^^^^^^^^^^^^^^^^^^^^^^^^^^^^^^^^^^
  File "C:\Users\katit\AppData\Local\Programs\Python\Python312\Lib\site-packages\django\contrib\admin\sites.py", line 259, in wrapper
    return self.admin_view(view, cacheable)(*args, **kwargs)
           ^^^^^^^^^^^^^^^^^^^^^^^^^^^^^^^^^^^^^^^^^^^^^^^^^
  File "C:\Users\katit\AppData\Local\Programs\Python\Python312\Lib\site-packages\django\utils\decorators.py", line 188, in _view_wrapper
    result = _process_exception(request, e)
             ^^^^^^^^^^^^^^^^^^^^^^^^^^^^^^
  File "C:\Users\katit\AppData\Local\Programs\Python\Python312\Lib\site-packages\django\utils\decorators.py", line 186, in _view_wrapper
    response = view_func(request, *args, **kwargs)
               ^^^^^^^^^^^^^^^^^^^^^^^^^^^^^^^^^^^
  File "C:\Users\katit\AppData\Local\Programs\Python\Python312\Lib\site-packages\django\views\decorators\cache.py", line 80, in _view_wrapper
    response = view_func(request, *args, **kwargs)
               ^^^^^^^^^^^^^^^^^^^^^^^^^^^^^^^^^^^
  File "C:\Users\katit\AppData\Local\Programs\Python\Python312\Lib\site-packages\django\contrib\admin\sites.py", line 228, in inner
    if not self.has_permission(request):
           ^^^^^^^^^^^^^^^^^^^^^^^^^^^^
  File "C:\Users\katit\AppData\Local\Programs\Python\Python312\Lib\site-packages\django\contrib\admin\sites.py", line 201, in has_permission
    return request.user.is_active and request.user.is_staff
           ^^^^^^^^^^^^^^^^^^^^^^
  File "C:\Users\katit\AppData\Local\Programs\Python\Python312\Lib\site-packages\django\utils\functional.py", line 251, in inner
    self._setup()
  File "C:\Users\katit\AppData\Local\Programs\Python\Python312\Lib\site-packages\django\utils\functional.py", line 404, in _setup
    self._wrapped = self._setupfunc()
                    ^^^^^^^^^^^^^^^^^
  File "C:\Users\katit\AppData\Local\Programs\Python\Python312\Lib\site-packages\django\contrib\auth\middleware.py", line 33, in <lambda>
    request.user = SimpleLazyObject(lambda: get_user(request))
                                            ^^^^^^^^^^^^^^^^^
  File "C:\Users\katit\AppData\Local\Programs\Python\Python312\Lib\site-packages\django\contrib\auth\middleware.py", line 13, in get_user
    request._cached_user = auth.get_user(request)
                           ^^^^^^^^^^^^^^^^^^^^^^
  File "C:\Users\katit\AppData\Local\Programs\Python\Python312\Lib\site-packages\django\contrib\auth\__init__.py", line 209, in get_user
    user_id = _get_user_session_key(request)
              ^^^^^^^^^^^^^^^^^^^^^^^^^^^^^^
  File "C:\Users\katit\AppData\Local\Programs\Python\Python312\Lib\site-packages\django\contrib\auth\__init__.py", line 62, in _get_user_session_key
    return get_user_model()._meta.pk.to_python(request.session[SESSION_KEY])
                                               ~~~~~~~~~~~~~~~^^^^^^^^^^^^^
  File "C:\Users\katit\AppData\Local\Programs\Python\Python312\Lib\site-packages\django\contrib\sessions\backends\base.py", line 53, in __getitem__
    return self._session[key]
           ^^^^^^^^^^^^^
  File "C:\Users\katit\AppData\Local\Programs\Python\Python312\Lib\site-packages\django\contrib\sessions\backends\base.py", line 192, in _get_session
    self._session_cache = self.load()
                          ^^^^^^^^^^^
  File "C:\Users\katit\AppData\Local\Programs\Python\Python312\Lib\site-packages\django\contrib\sessions\backends\db.py", line 42, in load
    s = self._get_session_from_db()
        ^^^^^^^^^^^^^^^^^^^^^^^^^^^
  File "C:\Users\katit\AppData\Local\Programs\Python\Python312\Lib\site-packages\django\contrib\sessions\backends\db.py", line 32, in _get_session_from_db
    return self.model.objects.get(
           ^^^^^^^^^^^^^^^^^^^^^^^
  File "C:\Users\katit\AppData\Local\Programs\Python\Python312\Lib\site-packages\django\db\models\manager.py", line 87, in manager_method
    return getattr(self.get_queryset(), name)(*args, **kwargs)
           ^^^^^^^^^^^^^^^^^^^^^^^^^^^^^^^^^^^^^^^^^^^^^^^^^^^
  File "C:\Users\katit\AppData\Local\Programs\Python\Python312\Lib\site-packages\django\db\models\query.py", line 645, in get
    num = len(clone)
          ^^^^^^^^^^
  File "C:\Users\katit\AppData\Local\Programs\Python\Python312\Lib\site-packages\django\db\models\query.py", line 382, in __len__
    self._fetch_all()
  File "C:\Users\katit\AppData\Local\Programs\Python\Python312\Lib\site-packages\django\db\models\query.py", line 1928, in _fetch_all
    self._result_cache = list(self._iterable_class(self))
                         ^^^^^^^^^^^^^^^^^^^^^^^^^^^^^^^^
  File "C:\Users\katit\AppData\Local\Programs\Python\Python312\Lib\site-packages\django\db\models\query.py", line 91, in __iter__
    results = compiler.execute_sql(
              ^^^^^^^^^^^^^^^^^^^^^
  File "C:\Users\katit\AppData\Local\Programs\Python\Python312\Lib\site-packages\django\db\models\sql\compiler.py", line 1562, in execute_sql
    cursor.execute(sql, params)
  File "C:\Users\katit\AppData\Local\Programs\Python\Python312\Lib\site-packages\django\db\backends\utils.py", line 122, in execute
    return super().execute(sql, params)
           ^^^^^^^^^^^^^^^^^^^^^^^^^^^^
  File "C:\Users\katit\AppData\Local\Programs\Python\Python312\Lib\site-packages\django\db\backends\utils.py", line 79, in execute
    return self._execute_with_wrappers(
           ^^^^^^^^^^^^^^^^^^^^^^^^^^^^
  File "C:\Users\katit\AppData\Local\Programs\Python\Python312\Lib\site-packages\django\db\backends\utils.py", line 92, in _execute_with_wrappers
    return executor(sql, params, many, context)
           ^^^^^^^^^^^^^^^^^^^^^^^^^^^^^^^^^^^^
  File "C:\Users\katit\AppData\Local\Programs\Python\Python312\Lib\site-packages\django\db\backends\utils.py", line 100, in _execute
    with self.db.wrap_database_errors:
  File "C:\Users\katit\AppData\Local\Programs\Python\Python312\Lib\site-packages\django\db\utils.py", line 91, in __exit__
    raise dj_exc_value.with_traceback(traceback) from exc_value
  File "C:\Users\katit\AppData\Local\Programs\Python\Python312\Lib\site-packages\django\db\backends\utils.py", line 105, in _execute
    return self.cursor.execute(sql, params)
           ^^^^^^^^^^^^^^^^^^^^^^^^^^^^^^^^
  File "C:\Users\katit\AppData\Local\Programs\Python\Python312\Lib\site-packages\django\db\backends\sqlite3\base.py", line 329, in execute
    return super().execute(query, params)
           ^^^^^^^^^^^^^^^^^^^^^^^^^^^^^^
django.db.utils.OperationalError: no such table: django_session
2024-06-29 03:26:27,873 ERROR Internal Server Error: /admin/
Traceback (most recent call last):
  File "C:\Users\katit\AppData\Local\Programs\Python\Python312\Lib\site-packages\django\contrib\sessions\backends\base.py", line 187, in _get_session
    return self._session_cache
           ^^^^^^^^^^^^^^^^^^^
AttributeError: 'SessionStore' object has no attribute '_session_cache'

During handling of the above exception, another exception occurred:

Traceback (most recent call last):
  File "C:\Users\katit\AppData\Local\Programs\Python\Python312\Lib\site-packages\django\db\backends\utils.py", line 105, in _execute
    return self.cursor.execute(sql, params)
           ^^^^^^^^^^^^^^^^^^^^^^^^^^^^^^^^
  File "C:\Users\katit\AppData\Local\Programs\Python\Python312\Lib\site-packages\django\db\backends\sqlite3\base.py", line 329, in execute
    return super().execute(query, params)
           ^^^^^^^^^^^^^^^^^^^^^^^^^^^^^^
sqlite3.OperationalError: no such table: django_session

The above exception was the direct cause of the following exception:

Traceback (most recent call last):
  File "C:\Users\katit\AppData\Local\Programs\Python\Python312\Lib\site-packages\django\core\handlers\exception.py", line 55, in inner
    response = get_response(request)
               ^^^^^^^^^^^^^^^^^^^^^
  File "C:\Users\katit\AppData\Local\Programs\Python\Python312\Lib\site-packages\django\core\handlers\base.py", line 197, in _get_response
    response = wrapped_callback(request, *callback_args, **callback_kwargs)
               ^^^^^^^^^^^^^^^^^^^^^^^^^^^^^^^^^^^^^^^^^^^^^^^^^^^^^^^^^^^^
  File "C:\Users\katit\AppData\Local\Programs\Python\Python312\Lib\site-packages\django\contrib\admin\sites.py", line 259, in wrapper
    return self.admin_view(view, cacheable)(*args, **kwargs)
           ^^^^^^^^^^^^^^^^^^^^^^^^^^^^^^^^^^^^^^^^^^^^^^^^^
  File "C:\Users\katit\AppData\Local\Programs\Python\Python312\Lib\site-packages\django\utils\decorators.py", line 188, in _view_wrapper
    result = _process_exception(request, e)
             ^^^^^^^^^^^^^^^^^^^^^^^^^^^^^^
  File "C:\Users\katit\AppData\Local\Programs\Python\Python312\Lib\site-packages\django\utils\decorators.py", line 186, in _view_wrapper
    response = view_func(request, *args, **kwargs)
               ^^^^^^^^^^^^^^^^^^^^^^^^^^^^^^^^^^^
  File "C:\Users\katit\AppData\Local\Programs\Python\Python312\Lib\site-packages\django\views\decorators\cache.py", line 80, in _view_wrapper
    response = view_func(request, *args, **kwargs)
               ^^^^^^^^^^^^^^^^^^^^^^^^^^^^^^^^^^^
  File "C:\Users\katit\AppData\Local\Programs\Python\Python312\Lib\site-packages\django\contrib\admin\sites.py", line 228, in inner
    if not self.has_permission(request):
           ^^^^^^^^^^^^^^^^^^^^^^^^^^^^
  File "C:\Users\katit\AppData\Local\Programs\Python\Python312\Lib\site-packages\django\contrib\admin\sites.py", line 201, in has_permission
    return request.user.is_active and request.user.is_staff
           ^^^^^^^^^^^^^^^^^^^^^^
  File "C:\Users\katit\AppData\Local\Programs\Python\Python312\Lib\site-packages\django\utils\functional.py", line 251, in inner
    self._setup()
  File "C:\Users\katit\AppData\Local\Programs\Python\Python312\Lib\site-packages\django\utils\functional.py", line 404, in _setup
    self._wrapped = self._setupfunc()
                    ^^^^^^^^^^^^^^^^^
  File "C:\Users\katit\AppData\Local\Programs\Python\Python312\Lib\site-packages\django\contrib\auth\middleware.py", line 33, in <lambda>
    request.user = SimpleLazyObject(lambda: get_user(request))
                                            ^^^^^^^^^^^^^^^^^
  File "C:\Users\katit\AppData\Local\Programs\Python\Python312\Lib\site-packages\django\contrib\auth\middleware.py", line 13, in get_user
    request._cached_user = auth.get_user(request)
                           ^^^^^^^^^^^^^^^^^^^^^^
  File "C:\Users\katit\AppData\Local\Programs\Python\Python312\Lib\site-packages\django\contrib\auth\__init__.py", line 209, in get_user
    user_id = _get_user_session_key(request)
              ^^^^^^^^^^^^^^^^^^^^^^^^^^^^^^
  File "C:\Users\katit\AppData\Local\Programs\Python\Python312\Lib\site-packages\django\contrib\auth\__init__.py", line 62, in _get_user_session_key
    return get_user_model()._meta.pk.to_python(request.session[SESSION_KEY])
                                               ~~~~~~~~~~~~~~~^^^^^^^^^^^^^
  File "C:\Users\katit\AppData\Local\Programs\Python\Python312\Lib\site-packages\django\contrib\sessions\backends\base.py", line 53, in __getitem__
    return self._session[key]
           ^^^^^^^^^^^^^
  File "C:\Users\katit\AppData\Local\Programs\Python\Python312\Lib\site-packages\django\contrib\sessions\backends\base.py", line 192, in _get_session
    self._session_cache = self.load()
                          ^^^^^^^^^^^
  File "C:\Users\katit\AppData\Local\Programs\Python\Python312\Lib\site-packages\django\contrib\sessions\backends\db.py", line 42, in load
    s = self._get_session_from_db()
        ^^^^^^^^^^^^^^^^^^^^^^^^^^^
  File "C:\Users\katit\AppData\Local\Programs\Python\Python312\Lib\site-packages\django\contrib\sessions\backends\db.py", line 32, in _get_session_from_db
    return self.model.objects.get(
           ^^^^^^^^^^^^^^^^^^^^^^^
  File "C:\Users\katit\AppData\Local\Programs\Python\Python312\Lib\site-packages\django\db\models\manager.py", line 87, in manager_method
    return getattr(self.get_queryset(), name)(*args, **kwargs)
           ^^^^^^^^^^^^^^^^^^^^^^^^^^^^^^^^^^^^^^^^^^^^^^^^^^^
  File "C:\Users\katit\AppData\Local\Programs\Python\Python312\Lib\site-packages\django\db\models\query.py", line 645, in get
    num = len(clone)
          ^^^^^^^^^^
  File "C:\Users\katit\AppData\Local\Programs\Python\Python312\Lib\site-packages\django\db\models\query.py", line 382, in __len__
    self._fetch_all()
  File "C:\Users\katit\AppData\Local\Programs\Python\Python312\Lib\site-packages\django\db\models\query.py", line 1928, in _fetch_all
    self._result_cache = list(self._iterable_class(self))
                         ^^^^^^^^^^^^^^^^^^^^^^^^^^^^^^^^
  File "C:\Users\katit\AppData\Local\Programs\Python\Python312\Lib\site-packages\django\db\models\query.py", line 91, in __iter__
    results = compiler.execute_sql(
              ^^^^^^^^^^^^^^^^^^^^^
  File "C:\Users\katit\AppData\Local\Programs\Python\Python312\Lib\site-packages\django\db\models\sql\compiler.py", line 1562, in execute_sql
    cursor.execute(sql, params)
  File "C:\Users\katit\AppData\Local\Programs\Python\Python312\Lib\site-packages\django\db\backends\utils.py", line 122, in execute
    return super().execute(sql, params)
           ^^^^^^^^^^^^^^^^^^^^^^^^^^^^
  File "C:\Users\katit\AppData\Local\Programs\Python\Python312\Lib\site-packages\django\db\backends\utils.py", line 79, in execute
    return self._execute_with_wrappers(
           ^^^^^^^^^^^^^^^^^^^^^^^^^^^^
  File "C:\Users\katit\AppData\Local\Programs\Python\Python312\Lib\site-packages\django\db\backends\utils.py", line 92, in _execute_with_wrappers
    return executor(sql, params, many, context)
           ^^^^^^^^^^^^^^^^^^^^^^^^^^^^^^^^^^^^
  File "C:\Users\katit\AppData\Local\Programs\Python\Python312\Lib\site-packages\django\db\backends\utils.py", line 100, in _execute
    with self.db.wrap_database_errors:
  File "C:\Users\katit\AppData\Local\Programs\Python\Python312\Lib\site-packages\django\db\utils.py", line 91, in __exit__
    raise dj_exc_value.with_traceback(traceback) from exc_value
  File "C:\Users\katit\AppData\Local\Programs\Python\Python312\Lib\site-packages\django\db\backends\utils.py", line 105, in _execute
    return self.cursor.execute(sql, params)
           ^^^^^^^^^^^^^^^^^^^^^^^^^^^^^^^^
  File "C:\Users\katit\AppData\Local\Programs\Python\Python312\Lib\site-packages\django\db\backends\sqlite3\base.py", line 329, in execute
    return super().execute(query, params)
           ^^^^^^^^^^^^^^^^^^^^^^^^^^^^^^
django.db.utils.OperationalError: no such table: django_session
2024-06-29 03:29:29,490 INFO Watching for file changes with StatReloader
2024-06-29 03:29:43,791 WARNING Not Found: /libros/
2024-06-29 03:29:46,922 WARNING Not Found: /libros/
